2019-01-30T16:01:57|CRITICAL|root|Unhandled exception:Traceback (most recent call last):
  File "C:\Users\aless\Anaconda3\lib\site-packages\ScopeFoundry\hardware.py", line 204, in enable_connection
    self.connect()
  File "C:\Users\aless\eclipse-workspace\Coherent_laser\laser_hardware.py", line 39, in connect
    self.read_from_hardware() #read from hardware at connection
  File "C:\Users\aless\Anaconda3\lib\site-packages\ScopeFoundry\hardware.py", line 181, in read_from_hardware
    lq.read_from_hardware()
  File "C:\Users\aless\Anaconda3\lib\site-packages\ScopeFoundry\logged_quantity.py", line 161, in read_from_hardware
    val = self.hardware_read_func()
  File "C:\Users\aless\eclipse-workspace\Coherent_laser\laser_device.py", line 58, in get_model
    fullresp = self.write_cmd('SYSTem:INFormation:MODel?')
  File "C:\Users\aless\eclipse-workspace\Coherent_laser\laser_device.py", line 25, in write_cmd
    self.ser.write(serialcmd.encode())
AttributeError: 'LaserDevice' object has no attribute 'ser'

During handling of the above exception, another exception occurred:

Traceback (most recent call last):
  File "C:\Users\aless\Anaconda3\lib\site-packages\ScopeFoundry\hardware.py", line 219, in enable_connection
    raise err
  File "C:\Users\aless\Anaconda3\lib\site-packages\ScopeFoundry\hardware.py", line 212, in enable_connection
    self.disconnect()
  File "C:\Users\aless\eclipse-workspace\Coherent_laser\laser_hardware.py", line 45, in disconnect
    self.laser.close()
  File "C:\Users\aless\eclipse-workspace\Coherent_laser\laser_device.py", line 21, in close
    self.ser.close()
AttributeError: 'LaserDevice' object has no attribute 'ser'

2019-01-30T16:01:57|CRITICAL|root|Unhandled exception:Traceback (most recent call last):
  File "C:\Users\aless\Anaconda3\lib\site-packages\ScopeFoundry\hardware.py", line 208, in enable_connection
    raise err
  File "C:\Users\aless\Anaconda3\lib\site-packages\ScopeFoundry\hardware.py", line 204, in enable_connection
    self.connect()
  File "C:\Users\aless\eclipse-workspace\Coherent_laser\laser_hardware.py", line 39, in connect
    self.read_from_hardware() #read from hardware at connection
  File "C:\Users\aless\Anaconda3\lib\site-packages\ScopeFoundry\hardware.py", line 181, in read_from_hardware
    lq.read_from_hardware()
  File "C:\Users\aless\Anaconda3\lib\site-packages\ScopeFoundry\logged_quantity.py", line 161, in read_from_hardware
    val = self.hardware_read_func()
  File "C:\Users\aless\eclipse-workspace\Coherent_laser\laser_device.py", line 58, in get_model
    fullresp = self.write_cmd('SYSTem:INFormation:MODel?')
  File "C:\Users\aless\eclipse-workspace\Coherent_laser\laser_device.py", line 25, in write_cmd
    self.ser.write(serialcmd.encode())
AttributeError: 'LaserDevice' object has no attribute 'ser'

2019-01-30T16:02:31|CRITICAL|root|Unhandled exception:Traceback (most recent call last):
  File "C:\Users\aless\Anaconda3\lib\site-packages\ScopeFoundry\logged_quantity.py", line 241, in update_value
    self.hardware_set_func(self.val)
  File "C:\Users\aless\eclipse-workspace\Coherent_laser\laser_device.py", line 154, in set_laser_power
    fullresp = self.write_cmd('SOURce:POWer:LEVel:IMMediate:AMPLitude '+str(value))
  File "C:\Users\aless\eclipse-workspace\Coherent_laser\laser_device.py", line 25, in write_cmd
    self.ser.write(serialcmd.encode())
AttributeError: 'LaserDevice' object has no attribute 'ser'

2019-01-30T16:02:35|CRITICAL|root|Unhandled exception:Traceback (most recent call last):
  File "C:\Users\aless\Anaconda3\lib\site-packages\ScopeFoundry\logged_quantity.py", line 241, in update_value
    self.hardware_set_func(self.val)
  File "C:\Users\aless\eclipse-workspace\Coherent_laser\laser_device.py", line 154, in set_laser_power
    fullresp = self.write_cmd('SOURce:POWer:LEVel:IMMediate:AMPLitude '+str(value))
  File "C:\Users\aless\eclipse-workspace\Coherent_laser\laser_device.py", line 25, in write_cmd
    self.ser.write(serialcmd.encode())
AttributeError: 'LaserDevice' object has no attribute 'ser'

2019-01-30T16:02:40|CRITICAL|root|Unhandled exception:Traceback (most recent call last):
  File "C:\Users\aless\Anaconda3\lib\site-packages\ScopeFoundry\logged_quantity.py", line 241, in update_value
    self.hardware_set_func(self.val)
  File "C:\Users\aless\eclipse-workspace\Coherent_laser\laser_device.py", line 154, in set_laser_power
    fullresp = self.write_cmd('SOURce:POWer:LEVel:IMMediate:AMPLitude '+str(value))
  File "C:\Users\aless\eclipse-workspace\Coherent_laser\laser_device.py", line 25, in write_cmd
    self.ser.write(serialcmd.encode())
AttributeError: 'LaserDevice' object has no attribute 'ser'

2019-01-30T16:03:05|CRITICAL|root|Unhandled exception:Traceback (most recent call last):
  File "C:\Users\aless\Anaconda3\lib\site-packages\ScopeFoundry\logged_quantity.py", line 241, in update_value
    self.hardware_set_func(self.val)
  File "C:\Users\aless\eclipse-workspace\Coherent_laser\laser_device.py", line 154, in set_laser_power
    fullresp = self.write_cmd('SOURce:POWer:LEVel:IMMediate:AMPLitude '+str(value))
  File "C:\Users\aless\eclipse-workspace\Coherent_laser\laser_device.py", line 25, in write_cmd
    self.ser.write(serialcmd.encode())
AttributeError: 'LaserDevice' object has no attribute 'ser'

