2019-02-07T16:02:13|CRITICAL|root|Unhandled exception:Traceback (most recent call last):
  File "C:\ProgramData\Anaconda3\lib\site-packages\ScopeFoundry\hardware.py", line 208, in enable_connection
    raise err
  File "C:\ProgramData\Anaconda3\lib\site-packages\ScopeFoundry\hardware.py", line 204, in enable_connection
    self.connect()
  File "C:\LabPrograms\Python\laser\laser_hardware.py", line 52, in connect
    self.laser_status.update_choice_index_value(self.laser_status.choices[new_choice_index][1])
NameError: name 'new_choice_index' is not defined

