2019-02-01T14:50:51|CRITICAL|root|Unhandled exception:Traceback (most recent call last):
  File "C:\Users\aless\Anaconda3\lib\site-packages\ScopeFoundry\hardware.py", line 208, in enable_connection
    raise err
  File "C:\Users\aless\Anaconda3\lib\site-packages\ScopeFoundry\hardware.py", line 204, in enable_connection
    self.connect()
  File "C:\Users\aless\eclipse-workspace\Coherent_laser\laser_hardware.py", line 34, in connect
    self.laser = LaserDevice(port=self.port.val, debug=self.debug_mode.val)
  File "C:\Users\aless\eclipse-workspace\Coherent_laser\laser_device.py", line 16, in __init__
    stopbits=1, xonxoff=False, timeout=3.0)
  File "C:\Users\aless\Anaconda3\lib\site-packages\serial\serialwin32.py", line 31, in __init__
    super(Serial, self).__init__(*args, **kwargs)
  File "C:\Users\aless\Anaconda3\lib\site-packages\serial\serialutil.py", line 240, in __init__
    self.open()
  File "C:\Users\aless\Anaconda3\lib\site-packages\serial\serialwin32.py", line 62, in open
    raise SerialException("could not open port {!r}: {!r}".format(self.portstr, ctypes.WinError()))
serial.serialutil.SerialException: could not open port '0': FileNotFoundError(2, 'The system cannot find the file specified.', None, 2)

