2019-02-07T16:16:12|CRITICAL|root|Unhandled exception:Traceback (most recent call last):
  File "C:\ProgramData\Anaconda3\lib\site-packages\ScopeFoundry\hardware.py", line 208, in enable_connection
    raise err
  File "C:\ProgramData\Anaconda3\lib\site-packages\ScopeFoundry\hardware.py", line 204, in enable_connection
    self.connect()
  File "C:\LabPrograms\Python\laser\laser_hardware.py", line 47, in connect
    self.laser_power.change_min_max(vmin=self.laser.get_minimum_power(), vmax=self.laser.get_maximum_power())
  File "C:\LabPrograms\Python\laser\laser_device.py", line 76, in get_minimum_power
    fullresp = self.write_cmd('SOURce:POWer:LIMit:LOW?')
  File "C:\LabPrograms\Python\laser\laser_device.py", line 35, in write_cmd
    return echo.replace('\r\n', '')
TypeError: a bytes-like object is required, not 'str'

