2019-01-30T16:07:42|CRITICAL|root|Unhandled exception:Traceback (most recent call last):
  File "C:\Users\aless\Anaconda3\lib\site-packages\ScopeFoundry\hardware.py", line 208, in enable_connection
    raise err
  File "C:\Users\aless\Anaconda3\lib\site-packages\ScopeFoundry\hardware.py", line 204, in enable_connection
    self.connect()
  File "C:\Users\aless\eclipse-workspace\Coherent_laser\laser_hardware.py", line 39, in connect
    self.read_from_hardware() #read from hardware at connection
  File "C:\Users\aless\Anaconda3\lib\site-packages\ScopeFoundry\hardware.py", line 181, in read_from_hardware
    lq.read_from_hardware()
  File "C:\Users\aless\Anaconda3\lib\site-packages\ScopeFoundry\logged_quantity.py", line 161, in read_from_hardware
    val = self.hardware_read_func()
  File "C:\Users\aless\eclipse-workspace\Coherent_laser\laser_device.py", line 58, in get_model
    fullresp = self.write_cmd('SYSTem:INFormation:MODel?')
  File "C:\Users\aless\eclipse-workspace\Coherent_laser\laser_device.py", line 25, in write_cmd
    self.ser.write(serialcmd.encode())
  File "C:\Users\aless\Anaconda3\lib\site-packages\serial\serialwin32.py", line 304, in write
    raise portNotOpenError
serial.serialutil.SerialException: Attempting to use a port that is not open

